Workbook
Name SQMAX: 'Mon programme'!$E$3
Name BNMAX: 'Mon programme'!$E$4
Name DLMAX: 'Mon programme'!$E$5

Sheet Mon programme
BC1: =IF(AN11="Squat",AQ11,"") | CM1: =IF(BX11="Squat",CA11,"") -> 3
D2: 1RM
D3: Squat | E3: 200 | F3: OBJECTIF DU BLOC : | I3: Relancer la machine
D4: Bench | E4: 140
D5: Deadlift | E5: 250
F7: Jour 1 : Squat 4/1/0 Bench volume | AP7: Jour 2 : Deadlift Larsen Bench | BZ7: Jour 3 : Bench Squat pause | DJ7: Jour 4 : SBD
O8: VOLUME S1J1 | AY8: VOLUME S1J1 | CI8: VOLUME S1J1 | DT8: VOLUME S1J1 | ER8: VOLUME S1J1
O9: squat | Q9: bench | S9: deadlift | U9: pecs | W9: dos | Y9: épaules | AA9: biceps | AC9: triceps | AE9: quads | AG9: ischios | AI9: fessier | AK9: mollets | AY9: squat | BA9: bench | BC9: deadlift | BE9: pecs | BG9: dos | BI9: épaules | BK9: biceps | BM9: triceps | BO9: quads | BQ9: ischios | BS9: fessier | BU9: mollets | CI9: squat | CK9: bench | CM9: deadlift | CO9: pecs | CQ9: dos | CS9: épaules | CU9: biceps | CW9: triceps | CY9: quads | DA9: ischios | DC9: fessier | DE9: mollets | DT9: squat | DV9: bench | DX9: deadlift | DZ9: pecs | EB9: dos | ED9: épaules | EF9: biceps | EH9: triceps | EJ9: quads | EL9: ischios | EN9: fessier | EP9: mollets | ER9: squat | ET9: bench | EV9: deadlift | EX9: pecs | EZ9: dos | FB9: épaules | FD9: biceps | FF9: triceps | FH9: quads | FJ9: ischios | FL9: fessier | FN9: mollets
D10: Type | E10: Muscle | F10: Exercices | G10: Sets | H10: Reps | I10: Intensité | J10: Charge | K10: RPE | L10: e1RM | M10: Notes | O10: Série | P10: Tonnage | Q10: Série | R10: Tonnage | S10: Série | T10: Tonnage | U10: Série | V10: Tonnage | W10: Série | X10: Tonnage | Y10: Série | Z10: Tonnage | AA10: Série | AB10: Tonnage | AC10: Série | AD10: Tonnage | AE10: Série | AF10: Tonnage | AG10: Série | AH10: Tonnage | AI10: Série | AJ10: Tonnage | AK10: Série | AL10: Tonnage | AN10: Type | AO10: Muscle | AP10: Exercices | AQ10: Sets | AR10: Reps | AS10: Intensité | AT10: Charge | AU10: RPE | AV10: e1RM | AW10: Notes | AY10: Série | AZ10: Tonnage | BA10: Série | BB10: Tonnage | BC10: Série | BD10: Tonnage | BE10: Série | BF10: Tonnage | BG10: Série | BH10: Tonnage | BI10: Série | BJ10: Tonnage | BK10: Série | BL10: Tonnage | BM10: Série | BN10: Tonnage | BO10: Série | BP10: Tonnage | BQ10: Série | BR10: Tonnage | BS10: Série | BT10: Tonnage | BU10: Série | BV10: Tonnage | BX10: Type | BY10: Muscle | BZ10: Exercices | CA10: Sets | CB10: Reps | CC10: Intensité | CD10: Charge | CE10: RPE | CF10: e1RM | CG10: Notes | CI10: Série | CJ10: Tonnage | CK10: Série | CL10: Tonnage | CM10: Série | CN10: Tonnage | CO10: Série | CP10: Tonnage | CQ10: Série | CR10: Tonnage | CS10: Série | CT10: Tonnage | CU10: Série | CV10: Tonnage | CW10: Série | CX10: Tonnage | CY10: Série | CZ10: Tonnage | DA10: Série | DB10: Tonnage | DC10: Série | DD10: Tonnage | DE10: Série | DF10: Tonnage | DH10: Type | DI10: Muscle | DJ10: Exercices | DK10: Sets | DL10: Reps | DM10: Intensité | DN10: Charge | DO10: RPE | DP10: e1RM | DQ10: Notes | DT10: Série | DU10: Tonnage | DV10: Série | DW10: Tonnage | DX10: Série | DY10: Tonnage | DZ10: Série | EA10: Tonnage | EB10: Série | EC10: Tonnage | ED10: Série | EE10: Tonnage | EF10: Série | EG10: Tonnage | EH10: Série | EI10: Tonnage | EJ10: Série | EK10: Tonnage | EL10: Série | EM10: Tonnage | EN10: Série | EO10: Tonnage | EP10: Série | EQ10: Tonnage | ER10: Série | ES10: Tonnage | ET10: Série | EU10: Tonnage | EV10: Série | EW10: Tonnage | EX10: Série | EY10: Tonnage | EZ10: Série | FA10: Tonnage | FB10: Série | FC10: Tonnage | FD10: Série | FE10: Tonnage | FF10: Série | FG10: Tonnage | FH10: Série | FI10: Tonnage | FJ10: Série | FK10: Tonnage | FL10: Série | FM10: Tonnage | FN10: Série | FO10: Tonnage
B11: Semaine 1 | D11: Squat | F11: Squat 4/1/0 | G11: 2 | H11: 5 | I11: 65 | J11: =IF(D11="Squat",IF(I11>10,MROUND((I11/100*SQMAX),2.5)," "),IF(D11="Bench",IF(I11>10,MROUND((I11/100*BNMAX),2.5)," "),IF(D11="Deadlift",IF(I11>10,MROUND((I11/100*DLMAX),2.5)," ")," "))) -> 130 | L11: =IFERROR((J11/VLOOKUP(K11,'RPE vs. %'!$D$3:$P$11,H11+1,FALSE)),"") | M11: Indiquer votre forme du jour, vos observations, blessures, ... | O11: =IF(D11="Squat",G11,"") -> 2 | P11: =IF(D11="Squat",G11*H11*J11,"") -> 1300 | Q11: =IF(D11="Bench",G11,"") | R11: =IF(D11="Bench",G11*H11*J11,"") | S11: =IF(D11="Deadlift",G11,"") | T11: =IF(D11="Deadlift",G11*H11*J11,"") | U11: =IF(E11="pecs",G11,"") | V11: =IF(E11="pecs",G11*H11*J11,"") | W11: =IF(E11="dos",G11,"") | X11: =IF(E11="dos",G11*H11*J11,"") | Y11: =IF(E11="épaules",G11,"") | Z11: =IF(E11="épaules",G11*H11*J11,"") | AA11: =IF(E11="biceps",G11,"") | AB11: =IF(E11="biceps",G11*H11*J11,"") | AC11: =IF(E11="triceps",G11,"") | AD11: =IF(E11="triceps",G11*H11*J11,"") | AE11: =IF(E11="quads",G11,"") | AF11: =IF(E11="quads",G11*H11*J11,"") | AG11: =IF(E11="ischios",G11,"") | AH11: =IF(E11="ischios",G11*H11*J11,"") | AI11: =IF(E11="fessier",G11,"") | AJ11: =IF(E11="fessier",G11*H11*J11,"") | AK11: =IF(E11="mollets",G11,"") | AL11: =IF(E11="mollets",G11*H11*J11,"") | AN11: Deadlift | AP11: Deadlift | AQ11: 3 | AR11: 3 | AS11: 80 | AT11: =IF(AN11="Squat",IF(AS11>10,MROUND((AS11/100*SQMAX),2.5)," "),IF(AN11="Bench",IF(AS11>10,MROUND((AS11/100*BNMAX),2.5)," "),IF(AN11="Deadlift",IF(AS11>10,MROUND((AS11/100*DLMAX),2.5)," ")," "))) -> 200 | AV11: =IFERROR((AT11/VLOOKUP(AU11,'RPE vs. %'!$D$3:$P$11,AR11+1,FALSE)),"") | AW11: Indiquer votre forme du jour, vos observations, blessures, ... | AY11: =IF(AN11="Squat",AQ11,"") | AZ11: =IF(AN11="Squat",AQ11*AR11*AT11,"") | BA11: =IF(AN11="Bench",AQ11,"") | BB11: =IF(AN11="Bench",AQ11*AR11*AT11,"") | BC11: =IF(AN11="Deadlift",AQ11,"") -> 3 | BD11: =IF(AN11="Deadlift",AQ11*AR11*AT11,"") -> 1800 | BE11: =IF(AO11="pecs",AQ11,"") | BF11: =IF(AO11="pecs",AQ11*AR11*AT11,"") | BG11: =IF(AO11="dos",AQ11,"") | BH11: =IF(AO11="dos",AQ11*AR11*AT11,"") | BI11: =IF(AO11="épaules",AQ11,"") | BJ11: =IF(AO11="épaules",AQ11*AR11*AT11,"") | BK11: =IF(AO11="biceps",AQ11,"") | BL11: =IF(AO11="biceps",AQ11*AR11*AT11,"") | BM11: =IF(AO11="triceps",AQ11,"") | BN11: =IF(AO11="triceps",AQ11*AR11*AT11,"") | BO11: =IF(AO11="quads",AQ11,"") | BP11: =IF(AO11="quads",AQ11*AR11*AT11,"") | BQ11: =IF(AO11="ischios",AQ11,"") | BR11: =IF(AO11="ischios",AQ11*AR11*AT11,"") | BS11: =IF(AO11="fessier",AQ11,"") | BT11: =IF(AO11="fessier",AQ11*AR11*AT11,"") | BU11: =IF(AO11="mollets",AQ11,"") | BV11: =IF(AO11="mollets",AQ11*AR11*AT11,"") | BX11: Squat | BZ11: Squat pause | CA11: 3 | CB11: 5 | CC11: 64 | CD11: =IF(BX11="Squat",IF(CC11>10,MROUND((CC11/100*SQMAX),2.5)," "),IF(BX11="Bench",IF(CC11>10,MROUND((CC11/100*BNMAX),2.5)," "),IF(BX11="Deadlift",IF(CC11>10,MROUND((CC11/100*DLMAX),2.5)," ")," "))) -> 127.5 | CF11: =IFERROR((CD11/VLOOKUP(CE11,'RPE vs. %'!$D$3:$P$11,CB11+1,FALSE)),"") | CG11: Indiquer votre forme du jour, vos observations, blessures, ... | CI11: =IF(BX11="Squat",CA11,"") -> 3 | CJ11: =IF(BX11="Squat",CA11*CB11*CD11,"") -> 1912.5 | CK11: =IF(BX11="Bench",CA11,"") | CL11: =IF(BX11="Bench",CA11*CB11*CD11,"") | CM11: =IF(BX11="Deadlift",CA11,"") | CN11: =IF(BX11="Deadlift",CA11*CB11*CD11,"") | CO11: =IF(BY11="pecs",CA11,"") | CP11: =IF(BY11="pecs",CA11*CB11*CD11,"") | CQ11: =IF(BY11="dos",CA11,"") | CR11: =IF(BY11="dos",CA11*CB11*CD11,"") | CS11: =IF(BY11="épaules",CA11,"") | CT11: =IF(BY11="épaules",CA11*CB11*CD11,"") | CU11: =IF(BY11="biceps",CA11,"") | CV11: =IF(BY11="biceps",CA11*CB11*CD11,"") | CW11: =IF(BY11="triceps",CA11,"") | CX11: =IF(BY11="triceps",CA11*CB11*CD11,"") | CY11: =IF(BY11="quads",CA11,"") | CZ11: =IF(BY11="quads",CA11*CB11*CD11,"") | DA11: =IF(BY11="ischios",CA11,"") | DB11: =IF(BY11="ischios",CA11*CB11*CD11,"") | DC11: =IF(BY11="fessier",CA11,"") | DD11: =IF(BY11="fessier",CA11*CB11*CD11,"") | DE11: =IF(BY11="mollets",CA11,"") | DF11: =IF(BY11="mollets",CA11*CB11*CD11,"") | DH11: Squat | DJ11: Squat | DK11: 3 | DL11: 3 | DM11: 82 | DN11: =IF(DH11="Squat",IF(DM11>10,MROUND((DM11/100*SQMAX),2.5)," "),IF(DH11="Bench",IF(DM11>10,MROUND((DM11/100*BNMAX),2.5)," "),IF(DH11="Deadlift",IF(DM11>10,MROUND((DM11/100*DLMAX),2.5)," ")," "))) -> 165 | DP11: =IFERROR((DN11/VLOOKUP(DO11,'RPE vs. %'!$D$3:$P$11,DL11+1,FALSE)),"") | DQ11: Indiquer votre forme du jour, vos observations, blessures, ... | DT11: =IF(DH11="Squat",DK11,"") -> 3 | DU11: =IF(DH11="Squat",DK11*DL11*DN11,"") -> 1485 | DV11: =IF(DH11="Bench",DK11,"") | DW11: =IF(DH11="Bench",DK11*DL11*DN11,"") | DX11: =IF(DH11="Deadlift",DK11,"") | DY11: =IF(DH11="Deadlift",DK11*DL11*DN11,"") | DZ11: =IF(DI11="pecs",DK11,"") | EA11: =IF(DI11="pecs",DK11*DL11*DN11,"") | EB11: =IF(DI11="dos",DK11,"") | EC11: =IF(DI11="dos",DK11*DL11*DN11,"") | ED11: =IF(DI11="épaules",DK11,"") | EE11: =IF(DI11="épaules",DK11*DL11*DN11,"") | EF11: =IF(DI11="biceps",DK11,"") | EG11: =IF(DI11="biceps",DK11*DL11*DN11,"") | EH11: =IF(DI11="triceps",DK11,"") | EI11: =IF(DI11="triceps",DK11*DL11*DN11,"") | EJ11: =IF(DI11="quads",DK11,"") | EK11: =IF(DI11="quads",DK11*DL11*DN11,"") | EL11: =IF(DI11="ischios",DK11,"") | EM11: =IF(DI11="ischios",DK11*DL11*DN11,"") | EN11: =IF(DI11="fessier",DK11,"") | EO11: =IF(DI11="fessier",DK11*DL11*DN11,"") | EP11: =IF(DI11="mollets",DK11,"") | EQ11: =IF(DI11="mollets",DK11*DL11*DN11,"") | ER11: =IF(#REF!="Squat",#REF!,"") -> #REF! | ES11: =IF(#REF!="Squat",#REF!*#REF!*#REF!,"") -> #REF! | ET11: =IF(#REF!="Bench",#REF!,"") -> #REF! | EU11: =IF(#REF!="Bench",#REF!*#REF!*#REF!,"") -> #REF! | EV11: =IF(#REF!="Deadlift",#REF!,"") -> #REF! | EW11: =IF(#REF!="Deadlift",#REF!*#REF!*#REF!,"") -> #REF! | EX11: =IF(#REF!="pecs",#REF!,"") -> #REF! | EY11: =IF(#REF!="pecs",#REF!*#REF!*#REF!,"") -> #REF! | EZ11: =IF(#REF!="dos",#REF!,"") -> #REF! | FA11: =IF(#REF!="dos",#REF!*#REF!*#REF!,"") -> #REF! | FB11: =IF(#REF!="épaules",#REF!,"") -> #REF! | FC11: =IF(#REF!="épaules",#REF!*#REF!*#REF!,"") -> #REF! | FD11: =IF(#REF!="biceps",#REF!,"") -> #REF! | FE11: =IF(#REF!="biceps",#REF!*#REF!*#REF!,"") -> #REF! | FF11: =IF(#REF!="triceps",#REF!,"") -> #REF! | FG11: =IF(#REF!="triceps",#REF!*#REF!*#REF!,"") -> #REF! | FH11: =IF(#REF!="quads",#REF!,"") -> #REF! | FI11: =IF(#REF!="quads",#REF!*#REF!*#REF!,"") -> #REF! | FJ11: =IF(#REF!="ischios",#REF!,"") -> #REF! | FK11: =IF(#REF!="ischios",#REF!*#REF!*#REF!,"") -> #REF! | FL11: =IF(#REF!="fessier",#REF!,"") -> #REF! | FM11: =IF(#REF!="fessier",#REF!*#REF!*#REF!,"") -> #REF! | FN11: =IF(#REF!="mollets",#REF!,"") -> #REF! | FO11: =IF(#REF!="mollets",#REF!*#REF!*#REF!,"") -> #REF!
D12: Squat | F12: Squat | G12: 1 | H12: 5 | I12: 72 | J12: =IF(D12="Squat",IF(I12>10,MROUND((I12/100*SQMAX),2.5)," "),IF(D12="Bench",IF(I12>10,MROUND((I12/100*BNMAX),2.5)," "),IF(D12="Deadlift",IF(I12>10,MROUND((I12/100*DLMAX),2.5)," ")," "))) -> 145 | L12: =IFERROR((J12/VLOOKUP(K12,'RPE vs. %'!$D$3:$P$11,H12+1,FALSE)),"") | O12: =IF(D12="Squat",G12,"") -> 1 | P12: =IF(D12="Squat",G12*H12*J12,"") -> 725 | Q12: =IF(D12="Bench",G12,"") | R12: =IF(D12="Bench",G12*H12*J12,"") | S12: =IF(D12="Deadlift",G12,"") | T12: =IF(D12="Deadlift",G12*H12*J12,"") | U12: =IF(E12="pecs",G12,"") | V12: =IF(E12="pecs",G12*H12*J12,"") | W12: =IF(E12="dos",G12,"") | X12: =IF(E12="dos",G12*H12*J12,"") | Y12: =IF(E12="épaules",G12,"") | Z12: =IF(E12="épaules",G12*H12*J12,"") | AA12: =IF(E12="biceps",G12,"") | AB12: =IF(E12="biceps",G12*H12*J12,"") | AC12: =IF(E12="triceps",G12,"") | AD12: =IF(E12="triceps",G12*H12*J12,"") | AE12: =IF(E12="quads",G12,"") | AF12: =IF(E12="quads",G12*H12*J12,"") | AG12: =IF(E12="ischios",G12,"") | AH12: =IF(E12="ischios",G12*H12*J12,"") | AI12: =IF(E12="fessier",G12,"") | AJ12: =IF(E12="fessier",G12*H12*J12,"") | AK12: =IF(E12="mollets",G12,"") | AL12: =IF(E12="mollets",G12*H12*J12,"") | AN12: Deadlift | AP12: Deadlift pause | AQ12: 2 | AR12: 5 | AS12: 60 | AT12: =IF(AN12="Squat",IF(AS12>10,MROUND((AS12/100*SQMAX),2.5)," "),IF(AN12="Bench",IF(AS12>10,MROUND((AS12/100*BNMAX),2.5)," "),IF(AN12="Deadlift",IF(AS12>10,MROUND((AS12/100*DLMAX),2.5)," ")," "))) -> 150 | AU12: 6 | AV12: =IFERROR((AT12/VLOOKUP(AU12,'RPE vs. %'!$D$3:$P$11,AR12+1,FALSE)),"") | AY12: =IF(AN12="Squat",AQ12,"") | AZ12: =IF(AN12="Squat",AQ12*AR12*AT12,"") | BA12: =IF(AN12="Bench",AQ12,"") | BB12: =IF(AN12="Bench",AQ12*AR12*AT12,"") | BC12: =IF(AN12="Deadlift",AQ12,"") -> 2 | BD12: =IF(AN12="Deadlift",AQ12*AR12*AT12,"") -> 1500 | BE12: =IF(AO12="pecs",AQ12,"") | BF12: =IF(AO12="pecs",AQ12*AR12*AT12,"") | BG12: =IF(AO12="dos",AQ12,"") | BH12: =IF(AO12="dos",AQ12*AR12*AT12,"") | BI12: =IF(AO12="épaules",AQ12,"") | BJ12: =IF(AO12="épaules",AQ12*AR12*AT12,"") | BK12: =IF(AO12="biceps",AQ12,"") | BL12: =IF(AO12="biceps",AQ12*AR12*AT12,"") | BM12: =IF(AO12="triceps",AQ12,"") | BN12: =IF(AO12="triceps",AQ12*AR12*AT12,"") | BO12: =IF(AO12="quads",AQ12,"") | BP12: =IF(AO12="quads",AQ12*AR12*AT12,"") | BQ12: =IF(AO12="ischios",AQ12,"") | BR12: =IF(AO12="ischios",AQ12*AR12*AT12,"") | BS12: =IF(AO12="fessier",AQ12,"") | BT12: =IF(AO12="fessier",AQ12*AR12*AT12,"") | BU12: =IF(AO12="mollets",AQ12,"") | BV12: =IF(AO12="mollets",AQ12*AR12*AT12,"") | BX12: Bench | BZ12: Bench | CA12: 4 | CB12: 2 | CC12: 90 | CD12: =IF(BX12="Squat",IF(CC12>10,MROUND((CC12/100*SQMAX),2.5)," "),IF(BX12="Bench",IF(CC12>10,MROUND((CC12/100*BNMAX),2.5)," "),IF(BX12="Deadlift",IF(CC12>10,MROUND((CC12/100*DLMAX),2.5)," ")," "))) -> 125 | CF12: =IFERROR((CD12/VLOOKUP(CE12,'RPE vs. %'!$D$3:$P$11,CB12+1,FALSE)),"") | CI12: =IF(BX12="Squat",CA12,"") | CJ12: =IF(BX12="Squat",CA12*CB12*CD12,"") | CK12: =IF(BX12="Bench",CA12,"") -> 4 | CL12: =IF(BX12="Bench",CA12*CB12*CD12,"") -> 1000 | CM12: =IF(BX12="Deadlift",CA12,"") | CN12: =IF(BX12="Deadlift",CA12*CB12*CD12,"") | CO12: =IF(BY12="pecs",CA12,"") | CP12: =IF(BY12="pecs",CA12*CB12*CD12,"") | CQ12: =IF(BY12="dos",CA12,"") | CR12: =IF(BY12="dos",CA12*CB12*CD12,"") | CS12: =IF(BY12="épaules",CA12,"") | CT12: =IF(BY12="épaules",CA12*CB12*CD12,"") | CU12: =IF(BY12="biceps",CA12,"") | CV12: =IF(BY12="biceps",CA12*CB12*CD12,"") | CW12: =IF(BY12="triceps",CA12,"") | CX12: =IF(BY12="triceps",CA12*CB12*CD12,"") | CY12: =IF(BY12="quads",CA12,"") | CZ12: =IF(BY12="quads",CA12*CB12*CD12,"") | DA12: =IF(BY12="ischios",CA12,"") | DB12: =IF(BY12="ischios",CA12*CB12*CD12,"") | DC12: =IF(BY12="fessier",CA12,"") | DD12: =IF(BY12="fessier",CA12*CB12*CD12,"") | DE12: =IF(BY12="mollets",CA12,"") | DF12: =IF(BY12="mollets",CA12*CB12*CD12,"") | DH12: Bench | DJ12: Bench | DK12: 3 | DL12: 3 | DM12: 82 | DN12: =IF(DH12="Squat",IF(DM12>10,MROUND((DM12/100*SQMAX),2.5)," "),IF(DH12="Bench",IF(DM12>10,MROUND((DM12/100*BNMAX),2.5)," "),IF(DH12="Deadlift",IF(DM12>10,MROUND((DM12/100*DLMAX),2.5)," ")," "))) -> 115 | DP12: =IFERROR((DN12/VLOOKUP(DO12,'RPE vs. %'!$D$3:$P$11,DL12+1,FALSE)),"") | DT12: =IF(DH12="Squat",DK12,"") | DU12: =IF(DH12="Squat",DK12*DL12*DN12,"") | DV12: =IF(DH12="Bench",DK12,"") -> 3 | DW12: =IF(DH12="Bench",DK12*DL12*DN12,"") -> 1035 | DX12: =IF(DH12="Deadlift",DK12,"") | DY12: =IF(DH12="Deadlift",DK12*DL12*DN12,"") | DZ12: =IF(DI12="pecs",DK12,"") | EA12: =IF(DI12="pecs",DK12*DL12*DN12,"") | EB12: =IF(DI12="dos",DK12,"") | EC12: =IF(DI12="dos",DK12*DL12*DN12,"") | ED12: =IF(DI12="épaules",DK12,"") | EE12: =IF(DI12="épaules",DK12*DL12*DN12,"") | EF12: =IF(DI12="biceps",DK12,"") | EG12: =IF(DI12="biceps",DK12*DL12*DN12,"") | EH12: =IF(DI12="triceps",DK12,"") | EI12: =IF(DI12="triceps",DK12*DL12*DN12,"") | EJ12: =IF(DI12="quads",DK12,"") | EK12: =IF(DI12="quads",DK12*DL12*DN12,"") | EL12: =IF(DI12="ischios",DK12,"") | EM12: =IF(DI12="ischios",DK12*DL12*DN12,"") | EN12: =IF(DI12="fessier",DK12,"") | EO12: =IF(DI12="fessier",DK12*DL12*DN12,"") | EP12: =IF(DI12="mollets",DK12,"") | EQ12: =IF(DI12="mollets",DK12*DL12*DN12,"") | ER12: =IF(#REF!="Squat",#REF!,"") -> #REF! | ES12: =IF(#REF!="Squat",#REF!*#REF!*#REF!,"") -> #REF! | ET12: =IF(#REF!="Bench",#REF!,"") -> #REF! | EU12: =IF(#REF!="Bench",#REF!*#REF!*#REF!,"") -> #REF! | EV12: =IF(#REF!="Deadlift",#REF!,"") -> #REF! | EW12: =IF(#REF!="Deadlift",#REF!*#REF!*#REF!,"") -> #REF! | EX12: =IF(#REF!="pecs",#REF!,"") -> #REF! | EY12: =IF(#REF!="pecs",#REF!*#REF!*#REF!,"") -> #REF! | EZ12: =IF(#REF!="dos",#REF!,"") -> #REF! | FA12: =IF(#REF!="dos",#REF!*#REF!*#REF!,"") -> #REF! | FB12: =IF(#REF!="épaules",#REF!,"") -> #REF! | FC12: =IF(#REF!="épaules",#REF!*#REF!*#REF!,"") -> #REF! | FD12: =IF(#REF!="biceps",#REF!,"") -> #REF! | FE12: =IF(#REF!="biceps",#REF!*#REF!*#REF!,"") -> #REF! | FF12: =IF(#REF!="triceps",#REF!,"") -> #REF! | FG12: =IF(#REF!="triceps",#REF!*#REF!*#REF!,"") -> #REF! | FH12: =IF(#REF!="quads",#REF!,"") -> #REF! | FI12: =IF(#REF!="quads",#REF!*#REF!*#REF!,"") -> #REF! | FJ12: =IF(#REF!="ischios",#REF!,"") -> #REF! | FK12: =IF(#REF!="ischios",#REF!*#REF!*#REF!,"") -> #REF! | FL12: =IF(#REF!="fessier",#REF!,"") -> #REF! | FM12: =IF(#REF!="fessier",#REF!*#REF!*#REF!,"") -> #REF! | FN12: =IF(#REF!="mollets",#REF!,"") -> #REF! | FO12: =IF(#REF!="mollets",#REF!*#REF!*#REF!,"") -> #REF!
D13: Bench | F13: Bench | G13: 3 | H13: 8 | I13: 70 | J13: =IF(D13="Squat",IF(I13>10,MROUND((I13/100*SQMAX),2.5)," "),IF(D13="Bench",IF(I13>10,MROUND((I13/100*BNMAX),2.5)," "),IF(D13="Deadlift",IF(I13>10,MROUND((I13/100*DLMAX),2.5)," ")," "))) -> 97.5 | L13: =IFERROR((J13/VLOOKUP(K13,'RPE vs. %'!$D$3:$P$11,H13+1,FALSE)),"") | O13: =IF(D13="Squat",G13,"") | P13: =IF(D13="Squat",G13*H13*J13,"") | Q13: =IF(D13="Bench",G13,"") -> 3 | R13: =IF(D13="Bench",G13*H13*J13,"") -> 2340 | S13: =IF(D13="Deadlift",G13,"") | T13: =IF(D13="Deadlift",G13*H13*J13,"") | U13: =IF(E13="pecs",G13,"") | V13: =IF(E13="pecs",G13*H13*J13,"") | W13: =IF(E13="dos",G13,"") | X13: =IF(E13="dos",G13*H13*J13,"") | Y13: =IF(E13="épaules",G13,"") | Z13: =IF(E13="épaules",G13*H13*J13,"") | AA13: =IF(E13="biceps",G13,"") | AB13: =IF(E13="biceps",G13*H13*J13,"") | AC13: =IF(E13="triceps",G13,"") | AD13: =IF(E13="triceps",G13*H13*J13,"") | AE13: =IF(E13="quads",G13,"") | AF13: =IF(E13="quads",G13*H13*J13,"") | AG13: =IF(E13="ischios",G13,"") | AH13: =IF(E13="ischios",G13*H13*J13,"") | AI13: =IF(E13="fessier",G13,"") | AJ13: =IF(E13="fessier",G13*H13*J13,"") | AK13: =IF(E13="mollets",G13,"") | AL13: =IF(E13="mollets",G13*H13*J13,"") | AN13: Bench | AP13: Bench larsen | AQ13: 3 | AR13: 5 | AS13: =80*0.8 -> 64 | AT13: =IF(AN13="Squat",IF(AS13>10,MROUND((AS13/100*SQMAX),2.5)," "),IF(AN13="Bench",IF(AS13>10,MROUND((AS13/100*BNMAX),2.5)," "),IF(AN13="Deadlift",IF(AS13>10,MROUND((AS13/100*DLMAX),2.5)," ")," "))) -> 90 | AV13: =IFERROR((AT13/VLOOKUP(AU13,'RPE vs. %'!$D$3:$P$11,AR13+1,FALSE)),"") | AY13: =IF(AN13="Squat",AQ13,"") | AZ13: =IF(AN13="Squat",AQ13*AR13*AT13,"") | BA13: =IF(AN13="Bench",AQ13,"") -> 3 | BB13: =IF(AN13="Bench",AQ13*AR13*AT13,"") -> 1350 | BC13: =IF(AN13="Deadlift",AQ13,"") | BD13: =IF(AN13="Deadlift",AQ13*AR13*AT13,"") | BE13: =IF(AO13="pecs",AQ13,"") | BF13: =IF(AO13="pecs",AQ13*AR13*AT13,"") | BG13: =IF(AO13="dos",AQ13,"") | BH13: =IF(AO13="dos",AQ13*AR13*AT13,"") | BI13: =IF(AO13="épaules",AQ13,"") | BJ13: =IF(AO13="épaules",AQ13*AR13*AT13,"") | BK13: =IF(AO13="biceps",AQ13,"") | BL13: =IF(AO13="biceps",AQ13*AR13*AT13,"") | BM13: =IF(AO13="triceps",AQ13,"") | BN13: =IF(AO13="triceps",AQ13*AR13*AT13,"") | BO13: =IF(AO13="quads",AQ13,"") | BP13: =IF(AO13="quads",AQ13*AR13*AT13,"") | BQ13: =IF(AO13="ischios",AQ13,"") | BR13: =IF(AO13="ischios",AQ13*AR13*AT13,"") | BS13: =IF(AO13="fessier",AQ13,"") | BT13: =IF(AO13="fessier",AQ13*AR13*AT13,"") | BU13: =IF(AO13="mollets",AQ13,"") | BV13: =IF(AO13="mollets",AQ13*AR13*AT13,"") | BX13: Bench | BZ13: Bench 2ct | CA13: 2 | CB13: 3 | CC13: 75 | CD13: =IF(BX13="Squat",IF(CC13>10,MROUND((CC13/100*SQMAX),2.5)," "),IF(BX13="Bench",IF(CC13>10,MROUND((CC13/100*BNMAX),2.5)," "),IF(BX13="Deadlift",IF(CC13>10,MROUND((CC13/100*DLMAX),2.5)," ")," "))) -> 105 | CF13: =IFERROR((CD13/VLOOKUP(CE13,'RPE vs. %'!$D$3:$P$11,CB13+1,FALSE)),"") | CI13: =IF(BX13="Squat",CA13,"") | CJ13: =IF(BX13="Squat",CA13*CB13*CD13,"") | CK13: =IF(BX13="Bench",CA13,"") -> 2 | CL13: =IF(BX13="Bench",CA13*CB13*CD13,"") -> 630 | CM13: =IF(BX13="Deadlift",CA13,"") | CN13: =IF(BX13="Deadlift",CA13*CB13*CD13,"") | CO13: =IF(BY13="pecs",CA13,"") | CP13: =IF(BY13="pecs",CA13*CB13*CD13,"") | CQ13: =IF(BY13="dos",CA13,"") | CR13: =IF(BY13="dos",CA13*CB13*CD13,"") | CS13: =IF(BY13="épaules",CA13,"") | CT13: =IF(BY13="épaules",CA13*CB13*CD13,"") | CU13: =IF(BY13="biceps",CA13,"") | CV13: =IF(BY13="biceps",CA13*CB13*CD13,"") | CW13: =IF(BY13="triceps",CA13,"") | CX13: =IF(BY13="triceps",CA13*CB13*CD13,"") | CY13: =IF(BY13="quads",CA13,"") | CZ13: =IF(BY13="quads",CA13*CB13*CD13,"") | DA13: =IF(BY13="ischios",CA13,"") | DB13: =IF(BY13="ischios",CA13*CB13*CD13,"") | DC13: =IF(BY13="fessier",CA13,"") | DD13: =IF(BY13="fessier",CA13*CB13*CD13,"") | DE13: =IF(BY13="mollets",CA13,"") | DF13: =IF(BY13="mollets",CA13*CB13*CD13,"") | DH13: Deadlift | DJ13: Deadlift | DK13: 3 | DL13: 3 | DM13: 82 | DN13: =IF(DH13="Squat",IF(DM13>10,MROUND((DM13/100*SQMAX),2.5)," "),IF(DH13="Bench",IF(DM13>10,MROUND((DM13/100*BNMAX),2.5)," "),IF(DH13="Deadlift",IF(DM13>10,MROUND((DM13/100*DLMAX),2.5)," ")," "))) -> 205 | DP13: =IFERROR((DN13/VLOOKUP(DO13,'RPE vs. %'!$D$3:$P$11,DL13+1,FALSE)),"") | DT13: =IF(DH13="Squat",DK13,"") | DU13: =IF(DH13="Squat",DK13*DL13*DN13,"") | DV13: =IF(DH13="Bench",DK13,"") | DW13: =IF(DH13="Bench",DK13*DL13*DN13,"") | DX13: =IF(DH13="Deadlift",DK13,"") -> 3 | DY13: =IF(DH13="Deadlift",DK13*DL13*DN13,"") -> 1845 | DZ13: =IF(DI13="pecs",DK13,"") | EA13: =IF(DI13="pecs",DK13*DL13*DN13,"") | EB13: =IF(DI13="dos",DK13,"") | EC13: =IF(DI13="dos",DK13*DL13*DN13,"") | ED13: =IF(DI13="épaules",DK13,"") | EE13: =IF(DI13="épaules",DK13*DL13*DN13,"") | EF13: =IF(DI13="biceps",DK13,"") | EG13: =IF(DI13="biceps",DK13*DL13*DN13,"") | EH13: =IF(DI13="triceps",DK13,"") | EI13: =IF(DI13="triceps",DK13*DL13*DN13,"") | EJ13: =IF(DI13="quads",DK13,"") | EK13: =IF(DI13="quads",DK13*DL13*DN13,"") | EL13: =IF(DI13="ischios",DK13,"") | EM13: =IF(DI13="ischios",DK13*DL13*DN13,"") | EN13: =IF(DI13="fessier",DK13,"") | EO13: =IF(DI13="fessier",DK13*DL13*DN13,"") | EP13: =IF(DI13="mollets",DK13,"") | EQ13: =IF(DI13="mollets",DK13*DL13*DN13,"") | ER13: =IF(#REF!="Squat",#REF!,"") -> #REF! | ES13: =IF(#REF!="Squat",#REF!*#REF!*#REF!,"") -> #REF! | ET13: =IF(#REF!="Bench",#REF!,"") -> #REF! | EU13: =IF(#REF!="Bench",#REF!*#REF!*#REF!,"") -> #REF! | EV13: =IF(#REF!="Deadlift",#REF!,"") -> #REF! | EW13: =IF(#REF!="Deadlift",#REF!*#REF!*#REF!,"") -> #REF! | EX13: =IF(#REF!="pecs",#REF!,"") -> #REF! | EY13: =IF(#REF!="pecs",#REF!*#REF!*#REF!,"") -> #REF! | EZ13: =IF(#REF!="dos",#REF!,"") -> #REF! | FA13: =IF(#REF!="dos",#REF!*#REF!*#REF!,"") -> #REF! | FB13: =IF(#REF!="épaules",#REF!,"") -> #REF! | FC13: =IF(#REF!="épaules",#REF!*#REF!*#REF!,"") -> #REF! | FD13: =IF(#REF!="biceps",#REF!,"") -> #REF! | FE13: =IF(#REF!="biceps",#REF!*#REF!*#REF!,"") -> #REF! | FF13: =IF(#REF!="triceps",#REF!,"") -> #REF! | FG13: =IF(#REF!="triceps",#REF!*#REF!*#REF!,"") -> #REF! | FH13: =IF(#REF!="quads",#REF!,"") -> #REF! | FI13: =IF(#REF!="quads",#REF!*#REF!*#REF!,"") -> #REF! | FJ13: =IF(#REF!="ischios",#REF!,"") -> #REF! | FK13: =IF(#REF!="ischios",#REF!*#REF!*#REF!,"") -> #REF! | FL13: =IF(#REF!="fessier",#REF!,"") -> #REF! | FM13: =IF(#REF!="fessier",#REF!*#REF!*#REF!,"") -> #REF! | FN13: =IF(#REF!="mollets",#REF!,"") -> #REF! | FO13: =IF(#REF!="mollets",#REF!*#REF!*#REF!,"") -> #REF!
D14: Renfo | F14: Hack squat | G14: 2 | H14: 45938 | J14: 100 | L14: =IFERROR((J14/VLOOKUP(K14,'RPE vs. %'!$D$3:$P$11,H14+1,FALSE)),"") | O14: =IF(D14="Squat",G14,"") | P14: =IF(D14="Squat",G14*H14*J14,"") | Q14: =IF(D14="Bench",G14,"") | R14: =IF(D14="Bench",G14*H14*J14,"") | S14: =IF(D14="Deadlift",G14,"") | T14: =IF(D14="Deadlift",G14*H14*J14,"") | U14: =IF(E14="pecs",G14,"") | V14: =IF(E14="pecs",G14*H14*J14,"") | W14: =IF(E14="dos",G14,"") | X14: =IF(E14="dos",G14*H14*J14,"") | Y14: =IF(E14="épaules",G14,"") | Z14: =IF(E14="épaules",G14*H14*J14,"") | AA14: =IF(E14="biceps",G14,"") | AB14: =IF(E14="biceps",G14*H14*J14,"") | AC14: =IF(E14="triceps",G14,"") | AD14: =IF(E14="triceps",G14*H14*J14,"") | AE14: =IF(E14="quads",G14,"") | AF14: =IF(E14="quads",G14*H14*J14,"") | AG14: =IF(E14="ischios",G14,"") | AH14: =IF(E14="ischios",G14*H14*J14,"") | AI14: =IF(E14="fessier",G14,"") | AJ14: =IF(E14="fessier",G14*H14*J14,"") | AK14: =IF(E14="mollets",G14,"") | AL14: =IF(E14="mollets",G14*H14*J14,"") | AN14: Renfo | AP14: Rdl uni | AQ14: 3 | AR14: 8 | AT14: 50 | AV14: =IFERROR((AT14/VLOOKUP(AU14,'RPE vs. %'!$D$3:$P$11,AR14+1,FALSE)),"") | AY14: =IF(AN14="Squat",AQ14,"") | AZ14: =IF(AN14="Squat",AQ14*AR14*AT14,"") | BA14: =IF(AN14="Bench",AQ14,"") | BB14: =IF(AN14="Bench",AQ14*AR14*AT14,"") | BC14: =IF(AN14="Deadlift",AQ14,"") | BD14: =IF(AN14="Deadlift",AQ14*AR14*AT14,"") | BE14: =IF(AO14="pecs",AQ14,"") | BF14: =IF(AO14="pecs",AQ14*AR14*AT14,"") | BG14: =IF(AO14="dos",AQ14,"") | BH14: =IF(AO14="dos",AQ14*AR14*AT14,"") | BI14: =IF(AO14="épaules",AQ14,"") | BJ14: =IF(AO14="épaules",AQ14*AR14*AT14,"") | BK14: =IF(AO14="biceps",AQ14,"") | BL14: =IF(AO14="biceps",AQ14*AR14*AT14,"") | BM14: =IF(AO14="triceps",AQ14,"") | BN14: =IF(AO14="triceps",AQ14*AR14*AT14,"") | BO14: =IF(AO14="quads",AQ14,"") | BP14: =IF(AO14="quads",AQ14*AR14*AT14,"") | BQ14: =IF(AO14="ischios",AQ14,"") | BR14: =IF(AO14="ischios",AQ14*AR14*AT14,"") | BS14: =IF(AO14="fessier",AQ14,"") | BT14: =IF(AO14="fessier",AQ14*AR14*AT14,"") | BU14: =IF(AO14="mollets",AQ14,"") | BV14: =IF(AO14="mollets",AQ14*AR14*AT14,"") | BX14: Renfo | BZ14: chest press | CA14: 3 | CB14: 12 | CD14: 60 | CF14: =IFERROR((CD14/VLOOKUP(CE14,'RPE vs. %'!$D$3:$P$11,CB14+1,FALSE)),"") | CI14: =IF(BX14="Squat",CA14,"") | CJ14: =IF(BX14="Squat",CA14*CB14*CD14,"") | CK14: =IF(BX14="Bench",CA14,"") | CL14: =IF(BX14="Bench",CA14*CB14*CD14,"") | CM14: =IF(BX14="Deadlift",CA14,"") | CN14: =IF(BX14="Deadlift",CA14*CB14*CD14,"") | CO14: =IF(BY14="pecs",CA14,"") | CP14: =IF(BY14="pecs",CA14*CB14*CD14,"") | CQ14: =IF(BY14="dos",CA14,"") | CR14: =IF(BY14="dos",CA14*CB14*CD14,"") | CS14: =IF(BY14="épaules",CA14,"") | CT14: =IF(BY14="épaules",CA14*CB14*CD14,"") | CU14: =IF(BY14="biceps",CA14,"") | CV14: =IF(BY14="biceps",CA14*CB14*CD14,"") | CW14: =IF(BY14="triceps",CA14,"") | CX14: =IF(BY14="triceps",CA14*CB14*CD14,"") | CY14: =IF(BY14="quads",CA14,"") | CZ14: =IF(BY14="quads",CA14*CB14*CD14,"") | DA14: =IF(BY14="ischios",CA14,"") | DB14: =IF(BY14="ischios",CA14*CB14*CD14,"") | DC14: =IF(BY14="fessier",CA14,"") | DD14: =IF(BY14="fessier",CA14*CB14*CD14,"") | DE14: =IF(BY14="mollets",CA14,"") | DF14: =IF(BY14="mollets",CA14*CB14*CD14,"") | DH14: Renfo | DJ14: Back extension | DK14: 5 | DL14: 12 | DN14: =IF(DH14="Squat",IF(DM14>10,MROUND((DM14/100*SQMAX),2.5)," "),IF(DH14="Bench",IF(DM14>10,MROUND((DM14/100*BNMAX),2.5)," "),IF(DH14="Deadlift",IF(DM14>10,MROUND((DM14/100*DLMAX),2.5)," ")," "))) | DP14: =IFERROR((DN14/VLOOKUP(DO14,'RPE vs. %'!$D$3:$P$11,DL14+1,FALSE)),"") | DT14: =IF(DH14="Squat",DK14,"") | DU14: =IF(DH14="Squat",DK14*DL14*DN14,"") | DV14: =IF(DH14="Bench",DK14,"") | DW14: =IF(DH14="Bench",DK14*DL14*DN14,"") | DX14: =IF(DH14="Deadlift",DK14,"") | DY14: =IF(DH14="Deadlift",DK14*DL14*DN14,"") | DZ14: =IF(DI14="pecs",DK14,"") | EA14: =IF(DI14="pecs",DK14*DL14*DN14,"") | EB14: =IF(DI14="dos",DK14,"") | EC14: =IF(DI14="dos",DK14*DL14*DN14,"") | ED14: =IF(DI14="épaules",DK14,"") | EE14: =IF(DI14="épaules",DK14*DL14*DN14,"") | EF14: =IF(DI14="biceps",DK14,"") | EG14: =IF(DI14="biceps",DK14*DL14*DN14,"") | EH14: =IF(DI14="triceps",DK14,"") | EI14: =IF(DI14="triceps",DK14*DL14*DN14,"") | EJ14: =IF(DI14="quads",DK14,"") | EK14: =IF(DI14="quads",DK14*DL14*DN14,"") | EL14: =IF(DI14="ischios",DK14,"") | EM14: =IF(DI14="ischios",DK14*DL14*DN14,"") | EN14: =IF(DI14="fessier",DK14,"") | EO14: =IF(DI14="fessier",DK14*DL14*DN14,"") | EP14: =IF(DI14="mollets",DK14,"") | EQ14: =IF(DI14="mollets",DK14*DL14*DN14,"") | ER14: =IF(#REF!="Squat",#REF!,"") -> #REF! | ES14: =IF(#REF!="Squat",#REF!*#REF!*#REF!,"") -> #REF! | ET14: =IF(#REF!="Bench",#REF!,"") -> #REF! | EU14: =IF(#REF!="Bench",#REF!*#REF!*#REF!,"") -> #REF! | EV14: =IF(#REF!="Deadlift",#REF!,"") -> #REF! | EW14: =IF(#REF!="Deadlift",#REF!*#REF!*#REF!,"") -> #REF! | EX14: =IF(#REF!="pecs",#REF!,"") -> #REF! | EY14: =IF(#REF!="pecs",#REF!*#REF!*#REF!,"") -> #REF! | EZ14: =IF(#REF!="dos",#REF!,"") -> #REF! | FA14: =IF(#REF!="dos",#REF!*#REF!*#REF!,"") -> #REF! | FB14: =IF(#REF!="épaules",#REF!,"") -> #REF! | FC14: =IF(#REF!="épaules",#REF!*#REF!*#REF!,"") -> #REF! | FD14: =IF(#REF!="biceps",#REF!,"") -> #REF! | FE14: =IF(#REF!="biceps",#REF!*#REF!*#REF!,"") -> #REF! | FF14: =IF(#REF!="triceps",#REF!,"") -> #REF! | FG14: =IF(#REF!="triceps",#REF!*#REF!*#REF!,"") -> #REF! | FH14: =IF(#REF!="quads",#REF!,"") -> #REF! | FI14: =IF(#REF!="quads",#REF!*#REF!*#REF!,"") -> #REF! | FJ14: =IF(#REF!="ischios",#REF!,"") -> #REF! | FK14: =IF(#REF!="ischios",#REF!*#REF!*#REF!,"") -> #REF! | FL14: =IF(#REF!="fessier",#REF!,"") -> #REF! | FM14: =IF(#REF!="fessier",#REF!*#REF!*#REF!,"") -> #REF! | FN14: =IF(#REF!="mollets",#REF!,"") -> #REF! | FO14: =IF(#REF!="mollets",#REF!*#REF!*#REF!,"") -> #REF!
D15: Renfo | F15: développer militaire | G15: 2 | H15: 8 | J15: 24 | L15: =IFERROR((J15/VLOOKUP(K15,'RPE vs. %'!$D$3:$P$11,H15+1,FALSE)),"") | O15: =IF(D15="Squat",G15,"") | P15: =IF(D15="Squat",G15*H15*J15,"") | Q15: =IF(D15="Bench",G15,"") | R15: =IF(D15="Bench",G15*H15*J15,"") | S15: =IF(D15="Deadlift",G15,"") | T15: =IF(D15="Deadlift",G15*H15*J15,"") | U15: =IF(E15="pecs",G15,"") | V15: =IF(E15="pecs",G15*H15*J15,"") | W15: =IF(E15="dos",G15,"") | X15: =IF(E15="dos",G15*H15*J15,"") | Y15: =IF(E15="épaules",G15,"") | Z15: =IF(E15="épaules",G15*H15*J15,"") | AA15: =IF(E15="biceps",G15,"") | AB15: =IF(E15="biceps",G15*H15*J15,"") | AC15: =IF(E15="triceps",G15,"") | AD15: =IF(E15="triceps",G15*H15*J15,"") | AE15: =IF(E15="quads",G15,"") | AF15: =IF(E15="quads",G15*H15*J15,"") | AG15: =IF(E15="ischios",G15,"") | AH15: =IF(E15="ischios",G15*H15*J15,"") | AI15: =IF(E15="fessier",G15,"") | AJ15: =IF(E15="fessier",G15*H15*J15,"") | AK15: =IF(E15="mollets",G15,"") | AL15: =IF(E15="mollets",G15*H15*J15,"") | AN15: Renfo | AP15: Back extension | AQ15: 5 | AR15: 12 | AT15: 20 | AV15: =IFERROR((AT15/VLOOKUP(AU15,'RPE vs. %'!$D$3:$P$11,AR15+1,FALSE)),"") | AY15: =IF(AN15="Squat",AQ15,"") | AZ15: =IF(AN15="Squat",AQ15*AR15*AT15,"") | BA15: =IF(AN15="Bench",AQ15,"") | BB15: =IF(AN15="Bench",AQ15*AR15*AT15,"") | BC15: =IF(AN15="Deadlift",AQ15,"") | BD15: =IF(AN15="Deadlift",AQ15*AR15*AT15,"") | BE15: =IF(AO15="pecs",AQ15,"") | BF15: =IF(AO15="pecs",AQ15*AR15*AT15,"") | BG15: =IF(AO15="dos",AQ15,"") | BH15: =IF(AO15="dos",AQ15*AR15*AT15,"") | BI15: =IF(AO15="épaules",AQ15,"") | BJ15: =IF(AO15="épaules",AQ15*AR15*AT15,"") | BK15: =IF(AO15="biceps",AQ15,"") | BL15: =IF(AO15="biceps",AQ15*AR15*AT15,"") | BM15: =IF(AO15="triceps",AQ15,"") | BN15: =IF(AO15="triceps",AQ15*AR15*AT15,"") | BO15: =IF(AO15="quads",AQ15,"") | BP15: =IF(AO15="quads",AQ15*AR15*AT15,"") | BQ15: =IF(AO15="ischios",AQ15,"") | BR15: =IF(AO15="ischios",AQ15*AR15*AT15,"") | BS15: =IF(AO15="fessier",AQ15,"") | BT15: =IF(AO15="fessier",AQ15*AR15*AT15,"") | BU15: =IF(AO15="mollets",AQ15,"") | BV15: =IF(AO15="mollets",AQ15*AR15*AT15,"") | BX15: Renfo | BZ15: Incliné haltère | CA15: 3 | CB15: 8 | CD15: =IF(BX15="Squat",IF(CC15>10,MROUND((CC15/100*SQMAX),2.5)," "),IF(BX15="Bench",IF(CC15>10,MROUND((CC15/100*BNMAX),2.5)," "),IF(BX15="Deadlift",IF(CC15>10,MROUND((CC15/100*DLMAX),2.5)," ")," "))) | CF15: =IFERROR((CD15/VLOOKUP(CE15,'RPE vs. %'!$D$3:$P$11,CB15+1,FALSE)),"") | CI15: =IF(BX15="Squat",CA15,"") | CJ15: =IF(BX15="Squat",CA15*CB15*CD15,"") | CK15: =IF(BX15="Bench",CA15,"") | CL15: =IF(BX15="Bench",CA15*CB15*CD15,"") | CM15: =IF(BX15="Deadlift",CA15,"") | CN15: =IF(BX15="Deadlift",CA15*CB15*CD15,"") | CO15: =IF(BY15="pecs",CA15,"") | CP15: =IF(BY15="pecs",CA15*CB15*CD15,"") | CQ15: =IF(BY15="dos",CA15,"") | CR15: =IF(BY15="dos",CA15*CB15*CD15,"") | CS15: =IF(BY15="épaules",CA15,"") | CT15: =IF(BY15="épaules",CA15*CB15*CD15,"") | CU15: =IF(BY15="biceps",CA15,"") | CV15: =IF(BY15="biceps",CA15*CB15*CD15,"") | CW15: =IF(BY15="triceps",CA15,"") | CX15: =IF(BY15="triceps",CA15*CB15*CD15,"") | CY15: =IF(BY15="quads",CA15,"") | CZ15: =IF(BY15="quads",CA15*CB15*CD15,"") | DA15: =IF(BY15="ischios",CA15,"") | DB15: =IF(BY15="ischios",CA15*CB15*CD15,"") | DC15: =IF(BY15="fessier",CA15,"") | DD15: =IF(BY15="fessier",CA15*CB15*CD15,"") | DE15: =IF(BY15="mollets",CA15,"") | DF15: =IF(BY15="mollets",CA15*CB15*CD15,"") | DH15: Renfo | DJ15: Back extension (coté) | DK15: 3 | DL15: 12 | DN15: =IF(DH15="Squat",IF(DM15>10,MROUND((DM15/100*SQMAX),2.5)," "),IF(DH15="Bench",IF(DM15>10,MROUND((DM15/100*BNMAX),2.5)," "),IF(DH15="Deadlift",IF(DM15>10,MROUND((DM15/100*DLMAX),2.5)," ")," "))) | DP15: =IFERROR((DN15/VLOOKUP(DO15,'RPE vs. %'!$D$3:$P$11,DL15+1,FALSE)),"") | DT15: =IF(DH15="Squat",DK15,"") | DU15: =IF(DH15="Squat",DK15*DL15*DN15,"") | DV15: =IF(DH15="Bench",DK15,"") | DW15: =IF(DH15="Bench",DK15*DL15*DN15,"") | DX15: =IF(DH15="Deadlift",DK15,"") | DY15: =IF(DH15="Deadlift",DK15*DL15*DN15,"") | DZ15: =IF(DI15="pecs",DK15,"") | EA15: =IF(DI15="pecs",DK15*DL15*DN15,"") | EB15: =IF(DI15="dos",DK15,"") | EC15: =IF(DI15="dos",DK15*DL15*DN15,"") | ED15: =IF(DI15="épaules",DK15,"") | EE15: =IF(DI15="épaules",DK15*DL15*DN15,"") | EF15: =IF(DI15="biceps",DK15,"") | EG15: =IF(DI15="biceps",DK15*DL15*DN15,"") | EH15: =IF(DI15="triceps",DK15,"") | EI15: =IF(DI15="triceps",DK15*DL15*DN15,"") | EJ15: =IF(DI15="quads",DK15,"") | EK15: =IF(DI15="quads",DK15*DL15*DN15,"") | EL15: =IF(DI15="ischios",DK15,"") | EM15: =IF(DI15="ischios",DK15*DL15*DN15,"") | EN15: =IF(DI15="fessier",DK15,"") | EO15: =IF(DI15="fessier",DK15*DL15*DN15,"") | EP15: =IF(DI15="mollets",DK15,"") | EQ15: =IF(DI15="mollets",DK15*DL15*DN15,"") | ER15: =IF(#REF!="Squat",#REF!,"") -> #REF! | ES15: =IF(#REF!="Squat",#REF!*#REF!*#REF!,"") -> #REF! | ET15: =IF(#REF!="Bench",#REF!,"") -> #REF! | EU15: =IF(#REF!="Bench",#REF!*#REF!*#REF!,"") -> #REF! | EV15: =IF(#REF!="Deadlift",#REF!,"") -> #REF! | EW15: =IF(#REF!="Deadlift",#REF!*#REF!*#REF!,"") -> #REF! | EX15: =IF(#REF!="pecs",#REF!,"") -> #REF! | EY15: =IF(#REF!="pecs",#REF!*#REF!*#REF!,"") -> #REF! | EZ15: =IF(#REF!="dos",#REF!,"") -> #REF! | FA15: =IF(#REF!="dos",#REF!*#REF!*#REF!,"") -> #REF! | FB15: =IF(#REF!="épaules",#REF!,"") -> #REF! | FC15: =IF(#REF!="épaules",#REF!*#REF!*#REF!,"") -> #REF! | FD15: =IF(#REF!="biceps",#REF!,"") -> #REF! | FE15: =IF(#REF!="biceps",#REF!*#REF!*#REF!,"") -> #REF! | FF15: =IF(#REF!="triceps",#REF!,"") -> #REF! | FG15: =IF(#REF!="triceps",#REF!*#REF!*#REF!,"") -> #REF! | FH15: =IF(#REF!="quads",#REF!,"") -> #REF! | FI15: =IF(#REF!="quads",#REF!*#REF!*#REF!,"") -> #REF! | FJ15: =IF(#REF!="ischios",#REF!,"") -> #REF! | FK15: =IF(#REF!="ischios",#REF!*#REF!*#REF!,"") -> #REF! | FL15: =IF(#REF!="fessier",#REF!,"") -> #REF! | FM15: =IF(#REF!="fessier",#REF!*#REF!*#REF!,"") -> #REF! | FN15: =IF(#REF!="mollets",#REF!,"") -> #REF! | FO15: =IF(#REF!="mollets",#REF!*#REF!*#REF!,"") -> #REF!
D16: Renfo | F16: élévation lateral | G16: 3 | H16: 12 | J16: 7.5 | L16: =IFERROR((J16/VLOOKUP(K16,'RPE vs. %'!$D$3:$P$11,H16+1,FALSE)),"") | O16: =IF(D16="Squat",G16,"") | P16: =IF(D16="Squat",G16*H16*J16,"") | Q16: =IF(D16="Bench",G16,"") | R16: =IF(D16="Bench",G16*H16*J16,"") | S16: =IF(D16="Deadlift",G16,"") | T16: =IF(D16="Deadlift",G16*H16*J16,"") | U16: =IF(E16="pecs",G16,"") | V16: =IF(E16="pecs",G16*H16*J16,"") | W16: =IF(E16="dos",G16,"") | X16: =IF(E16="dos",G16*H16*J16,"") | Y16: =IF(E16="épaules",G16,"") | Z16: =IF(E16="épaules",G16*H16*J16,"") | AA16: =IF(E16="biceps",G16,"") | AB16: =IF(E16="biceps",G16*H16*J16,"") | AC16: =IF(E16="triceps",G16,"") | AD16: =IF(E16="triceps",G16*H16*J16,"") | AE16: =IF(E16="quads",G16,"") | AF16: =IF(E16="quads",G16*H16*J16,"") | AG16: =IF(E16="ischios",G16,"") | AH16: =IF(E16="ischios",G16*H16*J16,"") | AI16: =IF(E16="fessier",G16,"") | AJ16: =IF(E16="fessier",G16*H16*J16,"") | AK16: =IF(E16="mollets",G16,"") | AL16: =IF(E16="mollets",G16*H16*J16,"") | AN16: Renfo | AP16: Traction | AQ16: 3 | AR16: 12 | AT16: 10 | AV16: =IFERROR((AT16/VLOOKUP(AU16,'RPE vs. %'!$D$3:$P$11,AR16+1,FALSE)),"") | AY16: =IF(AN16="Squat",AQ16,"") | AZ16: =IF(AN16="Squat",AQ16*AR16*AT16,"") | BA16: =IF(AN16="Bench",AQ16,"") | BB16: =IF(AN16="Bench",AQ16*AR16*AT16,"") | BC16: =IF(AN16="Deadlift",AQ16,"") | BD16: =IF(AN16="Deadlift",AQ16*AR16*AT16,"") | BE16: =IF(AO16="pecs",AQ16,"") | BF16: =IF(AO16="pecs",AQ16*AR16*AT16,"") | BG16: =IF(AO16="dos",AQ16,"") | BH16: =IF(AO16="dos",AQ16*AR16*AT16,"") | BI16: =IF(AO16="épaules",AQ16,"") | BJ16: =IF(AO16="épaules",AQ16*AR16*AT16,"") | BK16: =IF(AO16="biceps",AQ16,"") | BL16: =IF(AO16="biceps",AQ16*AR16*AT16,"") | BM16: =IF(AO16="triceps",AQ16,"") | BN16: =IF(AO16="triceps",AQ16*AR16*AT16,"") | BO16: =IF(AO16="quads",AQ16,"") | BP16: =IF(AO16="quads",AQ16*AR16*AT16,"") | BQ16: =IF(AO16="ischios",AQ16,"") | BR16: =IF(AO16="ischios",AQ16*AR16*AT16,"") | BS16: =IF(AO16="fessier",AQ16,"") | BT16: =IF(AO16="fessier",AQ16*AR16*AT16,"") | BU16: =IF(AO16="mollets",AQ16,"") | BV16: =IF(AO16="mollets",AQ16*AR16*AT16,"") | BX16: Renfo | BZ16: Extension triceps | CA16: 3 | CB16: 15 | CD16: =IF(BX16="Squat",IF(CC16>10,MROUND((CC16/100*SQMAX),2.5)," "),IF(BX16="Bench",IF(CC16>10,MROUND((CC16/100*BNMAX),2.5)," "),IF(BX16="Deadlift",IF(CC16>10,MROUND((CC16/100*DLMAX),2.5)," ")," "))) | CF16: =IFERROR((CD16/VLOOKUP(CE16,'RPE vs. %'!$D$3:$P$11,CB16+1,FALSE)),"") | CI16: =IF(BX16="Squat",CA16,"") | CJ16: =IF(BX16="Squat",CA16*CB16*CD16,"") | CK16: =IF(BX16="Bench",CA16,"") | CL16: =IF(BX16="Bench",CA16*CB16*CD16,"") | CM16: =IF(BX16="Deadlift",CA16,"") | CN16: =IF(BX16="Deadlift",CA16*CB16*CD16,"") | CO16: =IF(BY16="pecs",CA16,"") | CP16: =IF(BY16="pecs",CA16*CB16*CD16,"") | CQ16: =IF(BY16="dos",CA16,"") | CR16: =IF(BY16="dos",CA16*CB16*CD16,"") | CS16: =IF(BY16="épaules",CA16,"") | CT16: =IF(BY16="épaules",CA16*CB16*CD16,"") | CU16: =IF(BY16="biceps",CA16,"") | CV16: =IF(BY16="biceps",CA16*CB16*CD16,"") | CW16: =IF(BY16="triceps",CA16,"") | CX16: =IF(BY16="triceps",CA16*CB16*CD16,"") | CY16: =IF(BY16="quads",CA16,"") | CZ16: =IF(BY16="quads",CA16*CB16*CD16,"") | DA16: =IF(BY16="ischios",CA16,"") | DB16: =IF(BY16="ischios",CA16*CB16*CD16,"") | DC16: =IF(BY16="fessier",CA16,"") | DD16: =IF(BY16="fessier",CA16*CB16*CD16,"") | DE16: =IF(BY16="mollets",CA16,"") | DF16: =IF(BY16="mollets",CA16*CB16*CD16,"") | DN16: =IF(DH16="Squat",IF(DM16>10,MROUND((DM16/100*SQMAX),2.5)," "),IF(DH16="Bench",IF(DM16>10,MROUND((DM16/100*BNMAX),2.5)," "),IF(DH16="Deadlift",IF(DM16>10,MROUND((DM16/100*DLMAX),2.5)," ")," "))) | DP16: =IFERROR((DN16/VLOOKUP(DO16,'RPE vs. %'!$D$3:$P$11,DL16+1,FALSE)),"") | DT16: =IF(DH16="Squat",DK16,"") | DU16: =IF(DH16="Squat",DK16*DL16*DN16,"") | DV16: =IF(DH16="Bench",DK16,"") | DW16: =IF(DH16="Bench",DK16*DL16*DN16,"") | DX16: =IF(DH16="Deadlift",DK16,"") | DY16: =IF(DH16="Deadlift",DK16*DL16*DN16,"") | DZ16: =IF(DI16="pecs",DK16,"") | EA16: =IF(DI16="pecs",DK16*DL16*DN16,"") | EB16: =IF(DI16="dos",DK16,"") | EC16: =IF(DI16="dos",DK16*DL16*DN16,"") | ED16: =IF(DI16="épaules",DK16,"") | EE16: =IF(DI16="épaules",DK16*DL16*DN16,"") | EF16: =IF(DI16="biceps",DK16,"") | EG16: =IF(DI16="biceps",DK16*DL16*DN16,"") | EH16: =IF(DI16="triceps",DK16,"") | EI16: =IF(DI16="triceps",DK16*DL16*DN16,"") | EJ16: =IF(DI16="quads",DK16,"") | EK16: =IF(DI16="quads",DK16*DL16*DN16,"") | EL16: =IF(DI16="ischios",DK16,"") | EM16: =IF(DI16="ischios",DK16*DL16*DN16,"") | EN16: =IF(DI16="fessier",DK16,"") | EO16: =IF(DI16="fessier",DK16*DL16*DN16,"") | EP16: =IF(DI16="mollets",DK16,"") | EQ16: =IF(DI16="mollets",DK16*DL16*DN16,"") | ER16: =IF(#REF!="Squat",#REF!,"") -> #REF! | ES16: =IF(#REF!="Squat",#REF!*#REF!*#REF!,"") -> #REF! | ET16: =IF(#REF!="Bench",#REF!,"") -> #REF! | EU16: =IF(#REF!="Bench",#REF!*#REF!*#REF!,"") -> #REF! | EV16: =IF(#REF!="Deadlift",#REF!,"") -> #REF! | EW16: =IF(#REF!="Deadlift",#REF!*#REF!*#REF!,"") -> #REF! | EX16: =IF(#REF!="pecs",#REF!,"") -> #REF! | EY16: =IF(#REF!="pecs",#REF!*#REF!*#REF!,"") -> #REF! | EZ16: =IF(#REF!="dos",#REF!,"") -> #REF! | FA16: =IF(#REF!="dos",#REF!*#REF!*#REF!,"") -> #REF! | FB16: =IF(#REF!="épaules",#REF!,"") -> #REF! | FC16: =IF(#REF!="épaules",#REF!*#REF!*#REF!,"") -> #REF! | FD16: =IF(#REF!="biceps",#REF!,"") -> #REF! | FE16: =IF(#REF!="biceps",#REF!*#REF!*#REF!,"") -> #REF! | FF16: =IF(#REF!="triceps",#REF!,"") -> #REF! | FG16: =IF(#REF!="triceps",#REF!*#REF!*#REF!,"") -> #REF! | FH16: =IF(#REF!="quads",#REF!,"") -> #REF! | FI16: =IF(#REF!="quads",#REF!*#REF!*#REF!,"") -> #REF! | FJ16: =IF(#REF!="ischios",#REF!,"") -> #REF! | FK16: =IF(#REF!="ischios",#REF!*#REF!*#REF!,"") -> #REF! | FL16: =IF(#REF!="fessier",#REF!,"") -> #REF! | FM16: =IF(#REF!="fessier",#REF!*#REF!*#REF!,"") -> #REF! | FN16: =IF(#REF!="mollets",#REF!,"") -> #REF! | FO16: =IF(#REF!="mollets",#REF!*#REF!*#REF!,"") -> #REF!
J17: =IF(D17="Squat",IF(I17>10,MROUND((I17/100*SQMAX),2.5)," "),IF(D17="Bench",IF(I17>10,MROUND((I17/100*BNMAX),2.5)," "),IF(D17="Deadlift",IF(I17>10,MROUND((I17/100*DLMAX),2.5)," ")," "))) | L17: =IFERROR((J17/VLOOKUP(K17,'RPE vs. %'!$D$3:$P$11,H17+1,FALSE)),"") | O17: =IF(D17="Squat",G17,"") | P17: =IF(D17="Squat",G17*H17*J17,"") | Q17: =IF(D17="Bench",G17,"") | R17: =IF(D17="Bench",G17*H17*J17,"") | S17: =IF(D17="Deadlift",G17,"") | T17: =IF(D17="Deadlift",G17*H17*J17,"") | U17: =IF(E17="pecs",G17,"") | V17: =IF(E17="pecs",G17*H17*J17,"") | W17: =IF(E17="dos",G17,"") | X17: =IF(E17="dos",G17*H17*J17,"") | Y17: =IF(E17="épaules",G17,"") | Z17: =IF(E17="épaules",G17*H17*J17,"") | AA17: =IF(E17="biceps",G17,"") | AB17: =IF(E17="biceps",G17*H17*J17,"") | AC17: =IF(E17="triceps",G17,"") | AD17: =IF(E17="triceps",G17*H17*J17,"") | AE17: =IF(E17="quads",G17,"") | AF17: =IF(E17="quads",G17*H17*J17,"") | AG17: =IF(E17="ischios",G17,"") | AH17: =IF(E17="ischios",G17*H17*J17,"") | AI17: =IF(E17="fessier",G17,"") | AJ17: =IF(E17="fessier",G17*H17*J17,"") | AK17: =IF(E17="mollets",G17,"") | AL17: =IF(E17="mollets",G17*H17*J17,"") | AT17: =IF(AN17="Squat",IF(AS17>10,MROUND((AS17/100*SQMAX),2.5)," "),IF(AN17="Bench",IF(AS17>10,MROUND((AS17/100*BNMAX),2.5)," "),IF(AN17="Deadlift",IF(AS17>10,MROUND((AS17/100*DLMAX),2.5)," ")," "))) | AV17: =IFERROR((AT17/VLOOKUP(AU17,'RPE vs. %'!$D$3:$P$11,AR17+1,FALSE)),"") | AY17: =IF(AN17="Squat",AQ17,"") | AZ17: =IF(AN17="Squat",AQ17*AR17*AT17,"") | BA17: =IF(AN17="Bench",AQ17,"") | BB17: =IF(AN17="Bench",AQ17*AR17*AT17,"") | BC17: =IF(AN17="Deadlift",AQ17,"") | BD17: =IF(AN17="Deadlift",AQ17*AR17*AT17,"") | BE17: =IF(AO17="pecs",AQ17,"") | BF17: =IF(AO17="pecs",AQ17*AR17*AT17,"") | BG17: =IF(AO17="dos",AQ17,"") | BH17: =IF(AO17="dos",AQ17*AR17*AT17,"") | BI17: =IF(AO17="épaules",AQ17,"") | BJ17: =IF(AO17="épaules",AQ17*AR17*AT17,"") | BK17: =IF(AO17="biceps",AQ17,"") | BL17: =IF(AO17="biceps",AQ17*AR17*AT17,"") | BM17: =IF(AO17="triceps",AQ17,"") | BN17: =IF(AO17="triceps",AQ17*AR17*AT17,"") | BO17: =IF(AO17="quads",AQ17,"") | BP17: =IF(AO17="quads",AQ17*AR17*AT17,"") | BQ17: =IF(AO17="ischios",AQ17,"") | BR17: =IF(AO17="ischios",AQ17*AR17*AT17,"") | BS17: =IF(AO17="fessier",AQ17,"") | BT17: =IF(AO17="fessier",AQ17*AR17*AT17,"") | BU17: =IF(AO17="mollets",AQ17,"") | BV17: =IF(AO17="mollets",AQ17*AR17*AT17,"") | CD17: =IF(BX17="Squat",IF(CC17>10,MROUND((CC17/100*SQMAX),2.5)," "),IF(BX17="Bench",IF(CC17>10,MROUND((CC17/100*BNMAX),2.5)," "),IF(BX17="Deadlift",IF(CC17>10,MROUND((CC17/100*DLMAX),2.5)," ")," "))) | CF17: =IFERROR((CD17/VLOOKUP(CE17,'RPE vs. %'!$D$3:$P$11,CB17+1,FALSE)),"") | CI17: =IF(BX17="Squat",CA17,"") | CJ17: =IF(BX17="Squat",CA17*CB17*CD17,"") | CK17: =IF(BX17="Bench",CA17,"") | CL17: =IF(BX17="Bench",CA17*CB17*CD17,"") | CM17: =IF(BX17="Deadlift",CA17,"") | CN17: =IF(BX17="Deadlift",CA17*CB17*CD17,"") | CO17: =IF(BY17="pecs",CA17,"") | CP17: =IF(BY17="pecs",CA17*CB17*CD17,"") | CQ17: =IF(BY17="dos",CA17,"") | CR17: =IF(BY17="dos",CA17*CB17*CD17,"") | CS17: =IF(BY17="épaules",CA17,"") | CT17: =IF(BY17="épaules",CA17*CB17*CD17,"") | CU17: =IF(BY17="biceps",CA17,"") | CV17: =IF(BY17="biceps",CA17*CB17*CD17,"") | CW17: =IF(BY17="triceps",CA17,"") | CX17: =IF(BY17="triceps",CA17*CB17*CD17,"") | CY17: =IF(BY17="quads",CA17,"") | CZ17: =IF(BY17="quads",CA17*CB17*CD17,"") | DA17: =IF(BY17="ischios",CA17,"") | DB17: =IF(BY17="ischios",CA17*CB17*CD17,"") | DC17: =IF(BY17="fessier",CA17,"") | DD17: =IF(BY17="fessier",CA17*CB17*CD17,"") | DE17: =IF(BY17="mollets",CA17,"") | DF17: =IF(BY17="mollets",CA17*CB17*CD17,"") | DN17: =IF(DH17="Squat",IF(DM17>10,MROUND((DM17/100*SQMAX),2.5)," "),IF(DH17="Bench",IF(DM17>10,MROUND((DM17/100*BNMAX),2.5)," "),IF(DH17="Deadlift",IF(DM17>10,MROUND((DM17/100*DLMAX),2.5)," ")," "))) | DP17: =IFERROR((DN17/VLOOKUP(DO17,'RPE vs. %'!$D$3:$P$11,DL17+1,FALSE)),"") | DT17: =IF(DH17="Squat",DK17,"") | DU17: =IF(DH17="Squat",DK17*DL17*DN17,"") | DV17: =IF(DH17="Bench",DK17,"") | DW17: =IF(DH17="Bench",DK17*DL17*DN17,"") | DX17: =IF(DH17="Deadlift",DK17,"") | DY17: =IF(DH17="Deadlift",DK17*DL17*DN17,"") | DZ17: =IF(DI17="pecs",DK17,"") | EA17: =IF(DI17="pecs",DK17*DL17*DN17,"") | EB17: =IF(DI17="dos",DK17,"") | EC17: =IF(DI17="dos",DK17*DL17*DN17,"") | ED17: =IF(DI17="épaules",DK17,"") | EE17: =IF(DI17="épaules",DK17*DL17*DN17,"") | EF17: =IF(DI17="biceps",DK17,"") | EG17: =IF(DI17="biceps",DK17*DL17*DN17,"") | EH17: =IF(DI17="triceps",DK17,"") | EI17: =IF(DI17="triceps",DK17*DL17*DN17,"") | EJ17: =IF(DI17="quads",DK17,"") | EK17: =IF(DI17="quads",DK17*DL17*DN17,"") | EL17: =IF(DI17="ischios",DK17,"") | EM17: =IF(DI17="ischios",DK17*DL17*DN17,"") | EN17: =IF(DI17="fessier",DK17,"") | EO17: =IF(DI17="fessier",DK17*DL17*DN17,"") | EP17: =IF(DI17="mollets",DK17,"") | EQ17: =IF(DI17="mollets",DK17*DL17*DN17,"") | ER17: =IF(#REF!="Squat",#REF!,"") -> #REF! | ES17: =IF(#REF!="Squat",#REF!*#REF!*#REF!,"") -> #REF! | ET17: =IF(#REF!="Bench",#REF!,"") -> #REF! | EU17: =IF(#REF!="Bench",#REF!*#REF!*#REF!,"") -> #REF! | EV17: =IF(#REF!="Deadlift",#REF!,"") -> #REF! | EW17: =IF(#REF!="Deadlift",#REF!*#REF!*#REF!,"") -> #REF! | EX17: =IF(#REF!="pecs",#REF!,"") -> #REF! | EY17: =IF(#REF!="pecs",#REF!*#REF!*#REF!,"") -> #REF! | EZ17: =IF(#REF!="dos",#REF!,"") -> #REF! | FA17: =IF(#REF!="dos",#REF!*#REF!*#REF!,"") -> #REF! | FB17: =IF(#REF!="épaules",#REF!,"") -> #REF! | FC17: =IF(#REF!="épaules",#REF!*#REF!*#REF!,"") -> #REF! | FD17: =IF(#REF!="biceps",#REF!,"") -> #REF! | FE17: =IF(#REF!="biceps",#REF!*#REF!*#REF!,"") -> #REF! | FF17: =IF(#REF!="triceps",#REF!,"") -> #REF! | FG17: =IF(#REF!="triceps",#REF!*#REF!*#REF!,"") -> #REF! | FH17: =IF(#REF!="quads",#REF!,"") -> #REF! | FI17: =IF(#REF!="quads",#REF!*#REF!*#REF!,"") -> #REF! | FJ17: =IF(#REF!="ischios",#REF!,"") -> #REF! | FK17: =IF(#REF!="ischios",#REF!*#REF!*#REF!,"") -> #REF! | FL17: =IF(#REF!="fessier",#REF!,"") -> #REF! | FM17: =IF(#REF!="fessier",#REF!*#REF!*#REF!,"") -> #REF! | FN17: =IF(#REF!="mollets",#REF!,"") -> #REF! | FO17: =IF(#REF!="mollets",#REF!*#REF!*#REF!,"") -> #REF!
O18: =SUM(O11:O17) -> 3 | P18: =SUM(P11:P17) -> 2025 | Q18: =SUM(Q11:Q17) -> 3 | R18: =SUM(R11:R17) -> 2340 | S18: =SUM(S11:S17) -> 0 | T18: =SUM(T11:T17) -> 0 | U18: =SUM(U11:U17) -> 0 | V18: =SUM(V11:V17) -> 0 | ... AL18: =SUM(AL11:AL17) -> 0 | AY18: =SUM(AY11:AY17) -> 0 | AZ18: =SUM(AZ11:AZ17) -> 0 | BA18: =SUM(BA11:BA17) -> 3 | BB18: =SUM(BB11:BB17) -> 1350 | BC18: =SUM(BC11:BC17) -> 5 | BD18: =SUM(BD11:BD17) -> 3300 | BE18: =SUM(BE11:BE17) -> 0 | BF18: =SUM(BF11:BF17) -> 0 | ... BV18: =SUM(BV11:BV17) -> 0 | CI18: =SUM(CI11:CI17) -> 3 | CJ18: =SUM(CJ11:CJ17) -> 1912.5 | CK18: =SUM(CK11:CK17) -> 6 | CL18: =SUM(CL11:CL17) -> 1630 | CM18: =SUM(CM11:CM17) -> 0 | CN18: =SUM(CN11:CN17) -> 0 | CO18: =SUM(CO11:CO17) -> 0 | CP18: =SUM(CP11:CP17) -> 0 | ... DF18: =SUM(DF11:DF17) -> 0 | DT18: =SUM(DT11:DT17) -> 3 | DU18: =SUM(DU11:DU17) -> 1485 | DV18: =SUM(DV11:DV17) -> 3 | DW18: =SUM(DW11:DW17) -> 1035 | DX18: =SUM(DX11:DX17) -> 3 | DY18: =SUM(DY11:DY17) -> 1845 | DZ18: =SUM(DZ11:DZ17) -> 0 | EA18: =SUM(EA11:EA17) -> 0 | ... FO18: =SUM(FO11:FO17) -> #REF!
D19: Type | E19: Muscle | F19: Exercices | G19: Sets | H19: Reps | I19: Intensité | J19: Charge | K19: RPE | L19: e1RM | M19: Notes | O19: VOLUME S2J1 | AN19: Type | AO19: Muscle | AP19: Exercices | AQ19: Sets | AR19: Reps | AS19: Intensité | AT19: Charge | AU19: RPE | AV19: e1RM | AW19: Notes | AY19: VOLUME S2J1 | BX19: Type | BY19: Muscle | BZ19: Exercices | CA19: Sets | CB19: Reps | CC19: Intensité | CD19: Charge | CE19: RPE | CF19: e1RM | CG19: Notes | CI19: VOLUME S2J1 | DH19: Type | DI19: Muscle | DJ19: Exercices | DK19: Sets | DL19: Reps | DM19: Intensité | DN19: Charge | DO19: RPE | DP19: e1RM | DQ19: Notes | DT19: VOLUME S2J1 | ER19: VOLUME S2J1
B20: Semaine 2 | D20: =D11 -> Squat | E20: =E11 | F20: =F11 -> Squat 4/1/0 | G20: =G11 -> 2 | H20: =H11 -> 5 | I20: 70 | J20: =IF(D20="Squat",IF(I20>10,MROUND((I20/100*SQMAX),2.5)," "),IF(D20="Bench",IF(I20>10,MROUND((I20/100*BNMAX),2.5)," "),IF(D20="Deadlift",IF(I20>10,MROUND((I20/100*DLMAX),2.5)," ")," "))) -> 140 | K20: 7.5 | L20: =IFERROR((J20/VLOOKUP(K20,'RPE vs. %'!$D$3:$P$11,H20+1,FALSE)),"") -> 175.21902 | M20: Rowing 9,9,8 | O20: squat | Q20: bench | S20: deadlift | U20: pecs | W20: dos | Y20: épaules | AA20: biceps | AC20: triceps | AE20: quads | AG20: ischios | AI20: fessier | AK20: mollets | AN20: =AN11 -> Deadlift | AO20: =AO11 | AP20: =AP11 -> Deadlift | AQ20: =AQ11 -> 3 | AR20: =AR11 -> 3 | AS20: =AS11+3 -> 83 | AT20: =IF(AN20="Squat",IF(AS20>10,MROUND((AS20/100*SQMAX),2.5)," "),IF(AN20="Bench",IF(AS20>10,MROUND((AS20/100*BNMAX),2.5)," "),IF(AN20="Deadlift",IF(AS20>10,MROUND((AS20/100*DLMAX),2.5)," ")," "))) -> 207.5 | AV20: =IFERROR((AT20/VLOOKUP(AU20,'RPE vs. %'!$D$3:$P$11,AR20+1,FALSE)),"") | AW20: Indiquer votre forme du jour, vos observations, blessures, ... | AY20: squat | BA20: bench | BC20: deadlift | BE20: pecs | BG20: dos | BI20: épaules | BK20: biceps | BM20: triceps | BO20: quads | BQ20: ischios | BS20: fessier | BU20: mollets | BX20: =BX11 -> Squat | BY20: =BY11 | BZ20: =BZ11 -> Squat pause | CA20: =CA11 -> 3 | CB20: =CB11 -> 5 | CC20: =CC11+4 -> 68 | CD20: =IF(BX20="Squat",IF(CC20>10,MROUND((CC20/100*SQMAX),2.5)," "),IF(BX20="Bench",IF(CC20>10,MROUND((CC20/100*BNMAX),2.5)," "),IF(BX20="Deadlift",IF(CC20>10,MROUND((CC20/100*DLMAX),2.5)," ")," "))) -> 135 | CF20: =IFERROR((CD20/VLOOKUP(CE20,'RPE vs. %'!$D$3:$P$11,CB20+1,FALSE)),"") | CG20: Indiquer votre forme du jour, vos observations, blessures, ... | CI20: squat | CK20: bench | CM20: deadlift | CO20: pecs | CQ20: dos | CS20: épaules | CU20: biceps | CW20: triceps | CY20: quads | DA20: ischios | DC20: fessier | DE20: mollets | DH20: =DH11 -> Squat | DI20: =DI11 | DJ20: =DJ11 -> Squat | DK20: =DK11 -> 3 | DL20: =DL11 -> 3 | DM20: =DM11+3 -> 85 | DN20: =IF(DH20="Squat",IF(DM20>10,MROUND((DM20/100*SQMAX),2.5)," "),IF(DH20="Bench",IF(DM20>10,MROUND((DM20/100*BNMAX),2.5)," "),IF(DH20="Deadlift",IF(DM20>10,MROUND((DM20/100*DLMAX),2.5)," ")," "))) -> 170 | DP20: =IFERROR((DN20/VLOOKUP(DO20,'RPE vs. %'!$D$3:$P$11,DL20+1,FALSE)),"") | DQ20: Indiquer votre forme du jour, vos observations, blessures, ... | DT20: squat | DV20: bench | DX20: deadlift | DZ20: pecs | EB20: dos | ED20: épaules | EF20: biceps | EH20: triceps | EJ20: quads | EL20: ischios | EN20: fessier | EP20: mollets | ER20: squat | ET20: bench | EV20: deadlift | EX20: pecs | EZ20: dos | FB20: épaules | FD20: biceps | FF20: triceps | FH20: quads | FJ20: ischios | FL20: fessier | FN20: mollets
D21: =D12 -> Squat | E21: =E12 | F21: =F12 -> Squat | G21: =G12 -> 1 | H21: =H12 -> 5 | I21: =I12+3 -> 75 | J21: =IF(D21="Squat",IF(I21>10,MROUND((I21/100*SQMAX),2.5)," "),IF(D21="Bench",IF(I21>10,MROUND((I21/100*BNMAX),2.5)," "),IF(D21="Deadlift",IF(I21>10,MROUND((I21/100*DLMAX),2.5)," ")," "))) -> 150 | L21: =IFERROR((J21/VLOOKUP(K21,'RPE vs. %'!$D$3:$P$11,H21+1,FALSE)),"") | O21: Série | P21: Tonnage | Q21: Série | R21: Tonnage | S21: Série | T21: Tonnage | U21: Série | V21: Tonnage | W21: Série | X21: Tonnage | Y21: Série | Z21: Tonnage | AA21: Série | AB21: Tonnage | AC21: Série | AD21: Tonnage | AE21: Série | AF21: Tonnage | AG21: Série | AH21: Tonnage | AI21: Série | AJ21: Tonnage | AK21: Série | AL21: Tonnage | AN21: =AN12 -> Deadlift | AO21: =AO12 | AP21: =AP12 -> Deadlift pause | AQ21: =AQ12 -> 2 | AR21: =AR12 -> 5 | AS21: =AS12+3 -> 63 | AT21: =IF(AN21="Squat",IF(AS21>10,MROUND((AS21/100*SQMAX),2.5)," "),IF(AN21="Bench",IF(AS21>10,MROUND((AS21/100*BNMAX),2.5)," "),IF(AN21="Deadlift",IF(AS21>10,MROUND((AS21/100*DLMAX),2.5)," ")," "))) -> 157.5 | AV21: =IFERROR((AT21/VLOOKUP(AU21,'RPE vs. %'!$D$3:$P$11,AR21+1,FALSE)),"") | AY21: Série | AZ21: Tonnage | BA21: Série | BB21: Tonnage | BC21: Série | BD21: Tonnage | BE21: Série | BF21: Tonnage | BG21: Série | BH21: Tonnage | BI21: Série | BJ21: Tonnage | BK21: Série | BL21: Tonnage | BM21: Série | BN21: Tonnage | BO21: Série | BP21: Tonnage | BQ21: Série | BR21: Tonnage | BS21: Série | BT21: Tonnage | BU21: Série | BV21: Tonnage | BX21: =BX12 -> Bench | BY21: =BY12 | BZ21: =BZ12 -> Bench | CA21: =CA12 -> 4 | CB21: =CB12 -> 2 | CC21: 91 | CD21: =IF(BX21="Squat",IF(CC21>10,MROUND((CC21/100*SQMAX),2.5)," "),IF(BX21="Bench",IF(CC21>10,MROUND((CC21/100*BNMAX),2.5)," "),IF(BX21="Deadlift",IF(CC21>10,MROUND((CC21/100*DLMAX),2.5)," ")," "))) -> 127.5 | CF21: =IFERROR((CD21/VLOOKUP(CE21,'RPE vs. %'!$D$3:$P$11,CB21+1,FALSE)),"") | CI21: Série | CJ21: Tonnage | CK21: Série | CL21: Tonnage | CM21: Série | CN21: Tonnage | CO21: Série | CP21: Tonnage | CQ21: Série | CR21: Tonnage | CS21: Série | CT21: Tonnage | CU21: Série | CV21: Tonnage | CW21: Série | CX21: Tonnage | CY21: Série | CZ21: Tonnage | DA21: Série | DB21: Tonnage | DC21: Série | DD21: Tonnage | DE21: Série | DF21: Tonnage | DH21: =DH12 -> Bench | DI21: =DI12 | DJ21: =DJ12 -> Bench | DK21: =DK12 -> 3 | DL21: =DL12 -> 3 | DM21: =DM12+3 -> 85 | DN21: =IF(DH21="Squat",IF(DM21>10,MROUND((DM21/100*SQMAX),2.5)," "),IF(DH21="Bench",IF(DM21>10,MROUND((DM21/100*BNMAX),2.5)," "),IF(DH21="Deadlift",IF(DM21>10,MROUND((DM21/100*DLMAX),2.5)," ")," "))) -> 120 | DP21: =IFERROR((DN21/VLOOKUP(DO21,'RPE vs. %'!$D$3:$P$11,DL21+1,FALSE)),"") | DT21: Série | DU21: Tonnage | DV21: Série | DW21: Tonnage | DX21: Série | DY21: Tonnage | DZ21: Série | EA21: Tonnage | EB21: Série | EC21: Tonnage | ED21: Série | EE21: Tonnage | EF21: Série | EG21: Tonnage | EH21: Série | EI21: Tonnage | EJ21: Série | EK21: Tonnage | EL21: Série | EM21: Tonnage | EN21: Série | EO21: Tonnage | EP21: Série | EQ21: Tonnage | ER21: Série | ES21: Tonnage | ET21: Série | EU21: Tonnage | EV21: Série | EW21: Tonnage | EX21: Série | EY21: Tonnage | EZ21: Série | FA21: Tonnage | FB21: Série | FC21: Tonnage | FD21: Série | FE21: Tonnage | FF21: Série | FG21: Tonnage | FH21: Série | FI21: Tonnage | FJ21: Série | FK21: Tonnage | FL21: Série | FM21: Tonnage | FN21: Série | FO21: Tonnage
